Workbook

Sheet Übersicht
A1: Geratene R+F-Zuordnungen
A2: 91 GUT-Artikel, deren R+F-Entsprechung per Textsuche bestimmt wurde und nicht durch Rechnung, Lagerauszug oder Entscheidung belegt ist.
A3: Stand 13.09.2026 · Weich Energie · Aufmaß-Projekt
A5: So wird die Liste ausgefüllt
A6: Im Blatt „Zuordnungen“ sind nur die beiden gelben Spalten zu füllen:
A7: Spalte L „richtige R+F-Nummer“ die Artikelnummer, die stattdessen gilt
A8: Spalte M „Bemerkung“ etwa „wird nicht mehr verbaut“ oder „Preis prüfen“
A9: Alle übrigen Spalten bitte stehen lassen, sie sind die Grundlage für den Abgleich.
A11: Spalte K sagt, ob der zugeordnete R+F-Artikel überhaupt im Lagerauszug steht.
A12: Steht dort „nein“, lässt sich der Preis an nichts prüfen — dort lagen alle
A13: schweren Fehler, die bisher gefunden wurden.
A15: Beispielzeile
A16: GUT-Nummer | B16: richtige R+F-Nummer | C16: Bemerkung
A17: POVUS3525A | B17: 7020900559045 | C17: Prestabo läuft aus, Preis vom 28er übernommen
A18: Nur ein Beispiel für das Format — diese Zeile bitte nicht übertragen.
A21: Nach Kategorie
A22: Kategorie | B22: Artikel | C22: Warenwert | D22: davon ohne Regal-Gegenstück
A23: daemmung | B23: =COUNTIF(Zuordnungen!$A$2:$A$92,$A23) -> 10 | C23: =SUMIF(Zuordnungen!$A$2:$A$92,$A23,Zuordnungen!$H$2:$H$92) -> 2476 | D23: =COUNTIFS(Zuordnungen!$A$2:$A$92,$A23,Zuordnungen!$K$2:$K$92,"nein") -> 10
A24: formteil | B24: =COUNTIF(Zuordnungen!$A$2:$A$92,$A24) -> 44 | C24: =SUMIF(Zuordnungen!$A$2:$A$92,$A24,Zuordnungen!$H$2:$H$92) -> 4625 | D24: =COUNTIFS(Zuordnungen!$A$2:$A$92,$A24,Zuordnungen!$K$2:$K$92,"nein") -> 29
A25: rohr | B25: =COUNTIF(Zuordnungen!$A$2:$A$92,$A25) -> 7 | C25: =SUMIF(Zuordnungen!$A$2:$A$92,$A25,Zuordnungen!$H$2:$H$92) -> 1996 | D25: =COUNTIFS(Zuordnungen!$A$2:$A$92,$A25,Zuordnungen!$K$2:$K$92,"nein") -> 6
A26: schelle_zubehoer | B26: =COUNTIF(Zuordnungen!$A$2:$A$92,$A26) -> 2 | C26: =SUMIF(Zuordnungen!$A$2:$A$92,$A26,Zuordnungen!$H$2:$H$92) -> 82 | D26: =COUNTIFS(Zuordnungen!$A$2:$A$92,$A26,Zuordnungen!$K$2:$K$92,"nein") -> 2
A27: sonstiges | B27: =COUNTIF(Zuordnungen!$A$2:$A$92,$A27) -> 7 | C27: =SUMIF(Zuordnungen!$A$2:$A$92,$A27,Zuordnungen!$H$2:$H$92) -> 1245 | D27: =COUNTIFS(Zuordnungen!$A$2:$A$92,$A27,Zuordnungen!$K$2:$K$92,"nein") -> 6
A28: ungeklaert | B28: =COUNTIF(Zuordnungen!$A$2:$A$92,$A28) -> 14 | C28: =SUMIF(Zuordnungen!$A$2:$A$92,$A28,Zuordnungen!$H$2:$H$92) -> 680 | D28: =COUNTIFS(Zuordnungen!$A$2:$A$92,$A28,Zuordnungen!$K$2:$K$92,"nein") -> 14
A29: ventil | B29: =COUNTIF(Zuordnungen!$A$2:$A$92,$A29) -> 7 | C29: =SUMIF(Zuordnungen!$A$2:$A$92,$A29,Zuordnungen!$H$2:$H$92) -> 4879 | D29: =COUNTIFS(Zuordnungen!$A$2:$A$92,$A29,Zuordnungen!$K$2:$K$92,"nein") -> 6
A30: Summe | B30: =SUM(B23:B29) -> 91 | C30: =SUM(C23:C29) -> 15983 | D30: =SUM(D23:D29) -> 73

Sheet Zuordnungen
A1: Kategorie | B1: Formteil-Gruppe | C1: GUT-Nummer | D1: Bezeichnung | E1: Zusatz | F1: Menge | G1: zugeordneter EK | H1: Warenwert | I1: zugeordnete R+F-Nr | J1: R+F-Bezeichnung | K1: R+F im Lagerauszug | L1: richtige R+F-Nummer | M1: Bemerkung
A2: daemmung | C2: CLALUEND20SW | D2: Position gesperrt. Alu Endmanschettenband 20mm | E2: schwarz Rolle a 10m | F2: 0 | G2: 21.13 | I2: 1005060441030 | K2: nein
A3: daemmung | C3: CLALUEND30 | D3: Position gesperrt. Alu Endmanschettenband 30mm | E3: blank Rolle a 10m | F3: 0 | G3: 24.75 | I3: 1005060450030 | K3: nein
A4: ventil | C4: KHHM2532IVFGP | D4: Kugelhahn 1" x 1 1/4" mit Überwurfmutter | E4: und Plombierungsbohrung | F4: 91 | G4: 17.57 | H4: 3440 | I4: 1036285300000 | J4: WESA-Kugelhahn aus Pressmessing, PN 32, vernickelt, IG/Ü | K4: ja
A5: rohr | C5: CUS3512 | D5: Kupferrohr Sanco-DVGW EN 1057 35 x 1.2mm | E5: hart in Stangen R290 | F5: 60 | G5: 20.62 | H5: 1291 | I5: 1011960350012 | K5: nein
A6: daemmung | C6: COFALUK50 | D6: Alu-Klebeband CONEL 50mm breit | E6: Rolle a 100m | F6: 91 | G6: 11.7 | H6: 1206 | I6: 1005510050000 | K6: nein
A7: ventil | C7: KHDVGW15D | D7: KFE-Hahn DVGW-Ausführung 1/2" Durchgang | E7: vernickelt ohne Schlauchverschraubung | F7: 98 | G7: 10.43 | H7: 1070 | I7: 0000101130353 | K7: nein
A8: formteil | B8: rotguss-gewinde / 1" und groesser / gewinde | C8: 31302515 | D8: T-Stueck Rotguss 1"x 1/2"x 1" | E8: 3130 | F8: 68 | G8: 2.91 | H8: 910 | I8: 0000100322858 | K8: nein
A9: formteil | B9: rotguss-gewinde / 1" und groesser / gewinde | C9: 35302510R | D9: Langnippel Rotguss | E9: 1" x 100mm 3530 | F9: 59 | G9: 4.96 | H9: 600 | I9: 1014036110000 | J9: Doppelnippel aus RG/CuSi blank DN 15 (R 1/2) x 100 mm, M | K9: ja
A10: formteil | B10: connect-inox / 35mm und groesser / gewinde | C10: COCIUS3525ANL | D10: CONNECT INOX HEAT Übergangsstück | E10: 35 x 1" AG 1.4307 CONEL | F10: 56 | G10: 6.92 | H10: 486 | I10: 7085472283000 | J10: OptiSteel simplesta SH V Übergangsstück AG, d = 28 x R 1 | K10: ja
A11: daemmung | C11: COFW3530 | D11: CONEL FLEX WOOL Isolierschale, 100% | E11: 35x33mm, mit alukaschierter Folie, 1m | F11: 73 | G11: 2.02 | H11: 446 | I11: 1029988999086 | K11: nein
A12: sonstiges | C12: KV3390100L | D12: Flachheizkörper Kermi Profil V-Kompakt | E12: Typ 33 links 900x1000mm lackiert | F12: 1 | G12: 804.31 | H12: 432 | I12: 7089033809100 | K12: nein
A13: daemmung | C13: RORS8003520 | D13: Rohrschale 800 1000mm lang 35/20mm | E13: nach GEG 50% | F13: 71 | G13: 12.69 | H13: 375 | I13: 1005520054050 | K13: nein
A14: sonstiges | C14: 333132 | D14: Verschraubung Rotguss i/a 1 1/4" | E14: flachdichtend 3331 | F14: 8 | G14: 21.27 | H14: 332 | I14: 1014048300000 | J14: Rohrverschraubung aus RG/CuSi Nr.3331 R 1, flachdichtend | K14: ja
A15: rohr | C15: POVR35 | D15: Prestabo-Rohr 35 x 1,5 mm, Stange a 6m | E15: Stahl unlegiert, außen verzinkt | F15: 78 | G15: 5.54 | H15: 318 | I15: 7020900559496 | K15: nein
A16: formteil | B16: uponor-mlc / ohne Mass / gewinde | C16: UCUEK2522N | D16: Übergang Uponor auf Kupfer S-Press PLUS | E16: MLC U 25 x 22 Cu zum Pressen | F16: 26 | G16: 9.54 | H16: 316 | I16: 1029201070617 | J16: Uponor Übergang auf Kupfer S-Press PLUS 20-22CU | K16: ja
A17: sonstiges | C17: KV336080L | D17: Flachheizkörper Kermi Profil V-Kompakt | E17: Typ 33 links 600x 800mm lackiert | F17: 1 | G17: 610.23 | H17: 252 | I17: 0000100323437 | K17: nein
A18: formteil | B18: prestabo-stahl / 35mm und groesser / presse | C18: POVRS3522 | D18: Prestabo-Reduzierstück 35 x 22mm | E18: Stahl unlegiert,verzinkt, Einsteckende | F18: 74 | G18: 9.74 | H18: 239 | I18: 7020900558765 | K18: nein
A19: ventil | C19: ESSM661 | D19: ESBE ARA661 Stellmotor 3-Punkt 230V AC | E19: Laufzeit 90° 120s | F19: 2 | G19: 164.42 | H19: 222 | I19: 7076110095120 | K19: nein
A20: formteil | B20: connect-inox / 35mm und groesser / presse | C20: COCIT3515NL | D20: CONNECT INOX HEAT T-Stück 35x15x35mm | E20: 1.4307 CONEL | F20: 30 | G20: 14.55 | H20: 218 | I20: 7085929351000 | K20: nein
A21: formteil | B21: rotguss-gewinde / 1" und groesser / gewinde | C21: 35302015R | D21: Langnippel Rotguss | E21: 3/4" x 150mm 3530 | F21: 18 | G21: 13.44 | H21: 195 | I21: 1014036315000 | K21: nein
A22: sonstiges | C22: KV229040L | D22: Flachheizkörper Kermi Profil V-Kompakt | E22: Typ 22 links 900x 400mm lackiert | F22: 1 | G22: 332.1 | H22: 169 | I22: 7089022809040 | K22: nein
A23: rohr | C23: CUS22H | D23: Kupferrohr Sanco-DVGW EN 1057 22 x 1.0mm | E23: halbhart in Stangen R250 | F23: 15 | G23: 10.43 | H23: 167 | I23: 1011960220000 | K23: nein
A24: ungeklaert | C24: SSPT50 | D24: Siphon mit Leckwassertrichter DN 50 | E24: mit Wandhalterung, aus Kunststoff | F24: 37 | G24: 9.55 | H24: 164 | I24: 3059050000000 | K24: nein
A25: formteil | B25: rotguss-gewinde / 1" und groesser / gewinde | C25: 35302010R | D25: Langnippel Rotguss 3/4" x 100mm | E25: 3530 | F25: 24 | G25: 4.96 | H25: 160 | I25: 1014036110000 | J25: Doppelnippel aus RG/CuSi blank DN 15 (R 1/2) x 100 mm, M | K25: ja
A26: formteil | B26: gewinde-schwarz / 1" und groesser / gewinde | C26: NIPS256 | D26: Rohrdoppelnippel Nr.23 1" x 60mm | E26: schwarz | F26: 119 | G26: 1.01 | H26: 155 | I26: 0000100322582 | K26: nein
A27: formteil | B27: prestabo-stahl / 35mm und groesser / presse | C27: POVT3522 | D27: Prestabo-T-Stück 35 x 22 x 35mm | E27: Stahl unlegiert,verzinkt, Pressanschluss | F27: 13 | G27: 10.51 | H27: 153 | I27: 7020900558932 | K27: nein
A28: daemmung | C28: COFPUP3520 | D28: CONEL FLEX PUR Isolierschale, 50% | E28: 35x20mm, mit PVC Mantel, 1m | F28: 30 | G28: 5.76 | H28: 149 | I28: 1020141020000 | K28: nein
A29: rohr | C29: CUS281H | D29: Kupferrohr Sanco-DVGW EN 1057 28 x 1.0mm | E29: halbhart in Stangen R250 | F29: 10 | G29: 13.71 | H29: 143 | I29: 1011960281000 | K29: nein
A30: daemmung | C30: CLALUEND20 | D30: Position gesperrt. Alu Endmanschettenband 20mm | E30: blank Rolle a 10m | F30: 14 | G30: 21.85 | H30: 126 | I30: 1005060450020 | K30: nein
A31: formteil | B31: connect-inox / 22-28mm / gewinde | C31: COCIUS2825ANL | D31: CONNECT INOX HEAT Übergangsstück | E31: 28 x 1" AG 1.4307 CONEL | F31: 17 | G31: 6.92 | H31: 126 | I31: 7085472283000 | J31: OptiSteel simplesta SH V Übergangsstück AG, d = 28 x R 1 | K31: ja
A32: formteil | B32: uponor-mlc / ohne Mass / gewinde | C32: UCUEK1615N | D32: Übergang Uponor auf Kupfer S-Press PLUS | E32: MLC U 16 x 15 Cu | F32: 17 | G32: 7.08 | H32: 125 | I32: 1029201070615 | J32: Uponor Übergang auf Kupfer S-Press PLUS 16-15CU | K32: ja
A33: formteil | B33: gewinde-schwarz / 1" und groesser / gewinde | C33: NIPS2515 | D33: Rohrdoppelnippel Nr.23 1" x 150mm | E33: schwarz | F33: 60 | G33: 1.01 | H33: 118 | I33: 0000100322582 | K33: nein
A34: ungeklaert | C34: BMPMMEK10 | D34: Bördeladapter mit Messingmutter 3/8" | E34: mit Edelstahlkonus für Kälteanlagen | F34: 4 | G34: 30.18 | H34: 112 | I34: 2021521200038 | K34: nein
A35: daemmung | C35: COFALUK100 | D35: Alu-Klebeband CONEL 100mm breit | E35: Rolle a 100m | F35: 4 | G35: 17.45 | H35: 106 | I35: 2029840000043 | K35: nein
A36: schelle_zubehoer | C36: CSBLTH200 | D36: COSMO Tauchhülse DN15 L=200mm | E36: Messing vernickelt | F36: 8 | G36: 30.45 | H36: 82 | I36: 2023230979902 | K36: nein
A37: ventil | C37: ESBM3020MVN | D37: ESBE Brauchwassermischer Serie VTA322 | E37: 35-60 Grad mit Verschraubung 3/4" AG | F37: 1 | G37: 182.41 | H37: 75 | I37: 7076131400100 | K37: nein
A38: ungeklaert | C38: WFREN1603 | D38: Wickelfalzrohr verzinkt DN 160 | E38: nach DIN EN 12237 Länge 3 Meter | F38: 3 | G38: 10.34 | H38: 72 | I38: 2029415200300 | K38: nein
A39: ungeklaert | C39: CTG12 | D39: COSMO TW-Ausdehnungsgefäss 12 Ltr. weiss | E39: VD 4,0 bar, Btr.druck 10 bar durchströmt | F39: 1 | G39: 103.11 | H39: 71 | I39: 7008200024349 | K39: nein
A40: formteil | B40: gewinde-schwarz / 1" und groesser / gewinde | C40: 130S32 | D40: T-Stueck Nr.130 1 1/4" | E40: schwarz | F40: 20 | G40: 2.64 | H40: 69 | I40: 7075413300000 | J40: T-Stück Nr. 130, schwarz DN 25 (R 1) mit 3 I-Gewinden | K40: ja
...
